Traceback (most recent call last):
  File "C:\Users\crist\miniconda3\envs\ml_venv\lib\site-packages\jupyter_cache\executors\utils.py", line 58, in single_nb_execution
    executenb(
  File "C:\Users\crist\miniconda3\envs\ml_venv\lib\site-packages\nbclient\client.py", line 1305, in execute
    return NotebookClient(nb=nb, resources=resources, km=km, **kwargs).execute()
  File "C:\Users\crist\miniconda3\envs\ml_venv\lib\site-packages\jupyter_core\utils\__init__.py", line 166, in wrapped
    return loop.run_until_complete(inner)
  File "C:\Users\crist\miniconda3\envs\ml_venv\lib\asyncio\base_events.py", line 647, in run_until_complete
    return future.result()
  File "C:\Users\crist\miniconda3\envs\ml_venv\lib\site-packages\nbclient\client.py", line 705, in async_execute
    await self.async_execute_cell(
  File "C:\Users\crist\miniconda3\envs\ml_venv\lib\site-packages\nbclient\client.py", line 1058, in async_execute_cell
    await self._check_raise_for_error(cell, cell_index, exec_reply)
  File "C:\Users\crist\miniconda3\envs\ml_venv\lib\site-packages\nbclient\client.py", line 914, in _check_raise_for_error
    raise CellExecutionError.from_cell_and_msg(cell, exec_reply_content)
nbclient.exceptions.CellExecutionError: An error occurred while executing the following cell:
------------------
df_projections = pd.DataFrame(data=projections, columns=[f'x{i}' for i in range(1,4)])
df_projections
------------------


[1;31m---------------------------------------------------------------------------[0m
[1;31mNameError[0m                                 Traceback (most recent call last)
Cell [1;32mIn[9], line 1[0m
[1;32m----> 1[0m df_projections [38;5;241m=[39m pd[38;5;241m.[39mDataFrame(data[38;5;241m=[39m[43mprojections[49m, columns[38;5;241m=[39m[[38;5;124mf[39m[38;5;124m'[39m[38;5;124mx[39m[38;5;132;01m{[39;00mi[38;5;132;01m}[39;00m[38;5;124m'[39m [38;5;28;01mfor[39;00m i [38;5;129;01min[39;00m [38;5;28mrange[39m([38;5;241m1[39m,[38;5;241m4[39m)])
[0;32m      2[0m df_projections

[1;31mNameError[0m: name 'projections' is not defined

